2018-04-24 20:56:02,959 INFO: Microblog startup [in /Users/andreasantarlasci/Apps/microblog/app/__init__.py:45]
2018-04-24 20:56:07,051 ERROR: Exception on /login [GET] [in /Users/andreasantarlasci/Apps/microblog/venv/lib/python3.6/site-packages/flask/app.py:1560]
Traceback (most recent call last):
  File "/Users/andreasantarlasci/Apps/microblog/venv/lib/python3.6/site-packages/flask/app.py", line 1982, in wsgi_app
    response = self.full_dispatch_request()
  File "/Users/andreasantarlasci/Apps/microblog/venv/lib/python3.6/site-packages/flask/app.py", line 1614, in full_dispatch_request
    rv = self.handle_user_exception(e)
  File "/Users/andreasantarlasci/Apps/microblog/venv/lib/python3.6/site-packages/flask/app.py", line 1517, in handle_user_exception
    reraise(exc_type, exc_value, tb)
  File "/Users/andreasantarlasci/Apps/microblog/venv/lib/python3.6/site-packages/flask/_compat.py", line 33, in reraise
    raise value
  File "/Users/andreasantarlasci/Apps/microblog/venv/lib/python3.6/site-packages/flask/app.py", line 1612, in full_dispatch_request
    rv = self.dispatch_request()
  File "/Users/andreasantarlasci/Apps/microblog/venv/lib/python3.6/site-packages/flask/app.py", line 1598, in dispatch_request
    return self.view_functions[rule.endpoint](**req.view_args)
  File "/Users/andreasantarlasci/Apps/microblog/app/routes.py", line 52, in login
    return render_template('login.html', title='Sign In', form=form)
  File "/Users/andreasantarlasci/Apps/microblog/venv/lib/python3.6/site-packages/flask/templating.py", line 134, in render_template
    context, ctx.app)
  File "/Users/andreasantarlasci/Apps/microblog/venv/lib/python3.6/site-packages/flask/templating.py", line 116, in _render
    rv = template.render(context)
  File "/Users/andreasantarlasci/Apps/microblog/venv/lib/python3.6/site-packages/jinja2/asyncsupport.py", line 76, in render
    return original_render(self, *args, **kwargs)
  File "/Users/andreasantarlasci/Apps/microblog/venv/lib/python3.6/site-packages/jinja2/environment.py", line 1008, in render
    return self.environment.handle_exception(exc_info, True)
  File "/Users/andreasantarlasci/Apps/microblog/venv/lib/python3.6/site-packages/jinja2/environment.py", line 780, in handle_exception
    reraise(exc_type, exc_value, tb)
  File "/Users/andreasantarlasci/Apps/microblog/venv/lib/python3.6/site-packages/jinja2/_compat.py", line 37, in reraise
    raise value.with_traceback(tb)
  File "/Users/andreasantarlasci/Apps/microblog/app/templates/base.html", line 51, in template
    {% block content %}{% endblock %}
  File "/Users/andreasantarlasci/Apps/microblog/venv/lib/python3.6/site-packages/jinja2/environment.py", line 1005, in render
    return concat(self.root_render_func(self.new_context(vars)))
  File "/Users/andreasantarlasci/Apps/microblog/app/templates/login.html", line 1, in top-level template code
    {% extends "base.html" %}
  File "/Users/andreasantarlasci/Apps/microblog/venv/lib/python3.6/site-packages/jinja2/environment.py", line 780, in handle_exception
    reraise(exc_type, exc_value, tb)
  File "/Users/andreasantarlasci/Apps/microblog/venv/lib/python3.6/site-packages/jinja2/_compat.py", line 37, in reraise
    raise value.with_traceback(tb)
  File "/Users/andreasantarlasci/Apps/microblog/app/templates/base.html", line 51, in template
    {% block content %}{% endblock %}
  File "/Users/andreasantarlasci/Apps/microblog/venv/lib/python3.6/site-packages/jinja2/environment.py", line 543, in _generate
    optimized=self.optimized)
  File "/Users/andreasantarlasci/Apps/microblog/venv/lib/python3.6/site-packages/jinja2/compiler.py", line 82, in generate
    generator.visit(node)
  File "/Users/andreasantarlasci/Apps/microblog/venv/lib/python3.6/site-packages/jinja2/visitor.py", line 38, in visit
    return f(node, *args, **kwargs)
  File "/Users/andreasantarlasci/Apps/microblog/venv/lib/python3.6/site-packages/jinja2/compiler.py", line 718, in visit_Template
    self.fail('block %r defined twice' % block.name, block.lineno)
  File "/Users/andreasantarlasci/Apps/microblog/venv/lib/python3.6/site-packages/jinja2/compiler.py", line 315, in fail
    raise TemplateAssertionError(msg, lineno, self.name, self.filename)
jinja2.exceptions.TemplateAssertionError: block 'content' defined twice
2018-04-24 20:56:55,115 INFO: Microblog startup [in /Users/andreasantarlasci/Apps/microblog/app/__init__.py:45]
2018-04-24 20:58:05,656 INFO: Microblog startup [in /Users/andreasantarlasci/Apps/microblog/app/__init__.py:45]
2018-04-24 20:58:26,141 INFO: Microblog startup [in /Users/andreasantarlasci/Apps/microblog/app/__init__.py:45]
2018-04-24 21:02:26,848 INFO: Microblog startup [in /Users/andreasantarlasci/Apps/microblog/app/__init__.py:45]
2018-04-24 21:06:11,628 INFO: Microblog startup [in /Users/andreasantarlasci/Apps/microblog/app/__init__.py:45]
2018-04-24 21:07:17,470 INFO: Microblog startup [in /Users/andreasantarlasci/Apps/microblog/app/__init__.py:45]
2018-04-24 21:07:49,339 ERROR: Exception on /user/andreaS [GET] [in /Users/andreasantarlasci/Apps/microblog/venv/lib/python3.6/site-packages/flask/app.py:1560]
Traceback (most recent call last):
  File "/Users/andreasantarlasci/Apps/microblog/venv/lib/python3.6/site-packages/flask/app.py", line 1982, in wsgi_app
    response = self.full_dispatch_request()
  File "/Users/andreasantarlasci/Apps/microblog/venv/lib/python3.6/site-packages/flask/app.py", line 1614, in full_dispatch_request
    rv = self.handle_user_exception(e)
  File "/Users/andreasantarlasci/Apps/microblog/venv/lib/python3.6/site-packages/flask/app.py", line 1517, in handle_user_exception
    reraise(exc_type, exc_value, tb)
  File "/Users/andreasantarlasci/Apps/microblog/venv/lib/python3.6/site-packages/flask/_compat.py", line 33, in reraise
    raise value
  File "/Users/andreasantarlasci/Apps/microblog/venv/lib/python3.6/site-packages/flask/app.py", line 1612, in full_dispatch_request
    rv = self.dispatch_request()
  File "/Users/andreasantarlasci/Apps/microblog/venv/lib/python3.6/site-packages/flask/app.py", line 1598, in dispatch_request
    return self.view_functions[rule.endpoint](**req.view_args)
  File "/Users/andreasantarlasci/Apps/microblog/venv/lib/python3.6/site-packages/flask_login/utils.py", line 261, in decorated_view
    return func(*args, **kwargs)
  File "/Users/andreasantarlasci/Apps/microblog/app/routes.py", line 81, in user
    if post.has_next else None
NameError: name 'post' is not defined
2018-04-24 21:08:15,564 ERROR: Exception on /user/rachel [GET] [in /Users/andreasantarlasci/Apps/microblog/venv/lib/python3.6/site-packages/flask/app.py:1560]
Traceback (most recent call last):
  File "/Users/andreasantarlasci/Apps/microblog/venv/lib/python3.6/site-packages/flask/app.py", line 1982, in wsgi_app
    response = self.full_dispatch_request()
  File "/Users/andreasantarlasci/Apps/microblog/venv/lib/python3.6/site-packages/flask/app.py", line 1614, in full_dispatch_request
    rv = self.handle_user_exception(e)
  File "/Users/andreasantarlasci/Apps/microblog/venv/lib/python3.6/site-packages/flask/app.py", line 1517, in handle_user_exception
    reraise(exc_type, exc_value, tb)
  File "/Users/andreasantarlasci/Apps/microblog/venv/lib/python3.6/site-packages/flask/_compat.py", line 33, in reraise
    raise value
  File "/Users/andreasantarlasci/Apps/microblog/venv/lib/python3.6/site-packages/flask/app.py", line 1612, in full_dispatch_request
    rv = self.dispatch_request()
  File "/Users/andreasantarlasci/Apps/microblog/venv/lib/python3.6/site-packages/flask/app.py", line 1598, in dispatch_request
    return self.view_functions[rule.endpoint](**req.view_args)
  File "/Users/andreasantarlasci/Apps/microblog/venv/lib/python3.6/site-packages/flask_login/utils.py", line 261, in decorated_view
    return func(*args, **kwargs)
  File "/Users/andreasantarlasci/Apps/microblog/app/routes.py", line 81, in user
    if post.has_next else None
NameError: name 'post' is not defined
2018-04-24 21:10:05,792 INFO: Microblog startup [in /Users/andreasantarlasci/Apps/microblog/app/__init__.py:45]
